Workbook

Sheet Nucleos
A1: Empresa | B1: Setor | C1: Serviço | D1: Nome Setor | E1: Nome Contrato | F1: Nucleo | G1: Regional | H1: CodEmpresa | I1: Chave | J1: EmpresaOPTZ
A2: OPÇAO | B2: CBA | C2: FRETAMENTO | D2: CBA ALUMINIO (SCB) | E2: SCB_CBA [ALUMINIO] | F2: SOROCABA | G2: SPO | H2: 9 | I2: =SetorNucleo[[#This Row],[Empresa]]&SetorNucleo[[#This Row],[Setor]] -> OPÇAOCBA | J2: OPÇ
A3: OPÇAO | B3: CVV | C3: FRETAMENTO | D3: CONSORCIO VALE VERDE (BHZ) | E3: BHZ_CONSTRUTORA VALE VERDE [BARÃO DE COCAIS] | F3: BELO HORIZONTE | G3: SPO | H3: 9 | I3: =SetorNucleo[[#This Row],[Empresa]]&SetorNucleo[[#This Row],[Setor]] -> OPÇAOCVV | J3: OPÇ
A4: COMETA | B4: AQA | C4: RODOVIARIO | D4: ARARAQUARA | F4: INTERIOR SP | G4: SPO | H4: 3 | I4: =SetorNucleo[[#This Row],[Empresa]]&SetorNucleo[[#This Row],[Setor]] -> COMETAAQA | J4: COM
A5: AV1001 URB | B5: ARA | C5: URBANO | D5: ARARUAMA - URBANO | F5: MARUI | G5: RIO | H5: AV1001 URB | I5: =SetorNucleo[[#This Row],[Empresa]]&SetorNucleo[[#This Row],[Setor]] -> AV1001 URBARA | J5: 1001_URB
A6: COMETA | B6: JDG | C6: FRETAMENTO | D6: GLOBAL TECH (JDI) | E6: CPN_AMBEV GLOBAL [CAMPINAS] | F6: JUNDIAÍ | G6: SPO | H6: 3 | I6: =SetorNucleo[[#This Row],[Empresa]]&SetorNucleo[[#This Row],[Setor]] -> COMETAJDG | J6: COM
A7: COMETA | B7: BHI | C7: INTERMITENTE | D7: BELO HORIZONTE | F7: BELO HORIZONTE | G7: SPO | H7: 5 | I7: =SetorNucleo[[#This Row],[Empresa]]&SetorNucleo[[#This Row],[Setor]] -> COMETABHI | J7: COM
A8: COMETA | B8: BHW | C8: RODOVIARIO | D8: BELO HORIZONTE | F8: BELO HORIZONTE | G8: SPO | H8: 3 | I8: =SetorNucleo[[#This Row],[Empresa]]&SetorNucleo[[#This Row],[Setor]] -> COMETABHW | J8: COM
A9: COMETA | B9: BHZ | C9: RODOVIARIO | D9: BELO HORIZONTE | F9: BELO HORIZONTE | G9: SPO | H9: 3 | I9: =SetorNucleo[[#This Row],[Empresa]]&SetorNucleo[[#This Row],[Setor]] -> COMETABHZ | J9: COM
A10: COMETA | B10: PEG | C10: FRETAMENTO | D10: PEPSICO GUARULHOS (SAO) | E10: SAO_PEPSICO [GUARULHOS] | F10: SAO PAULO G1 | G10: SPO | H10: 3 | I10: =SetorNucleo[[#This Row],[Empresa]]&SetorNucleo[[#This Row],[Setor]] -> COMETAPEG | J10: COM
A11: CATARINENSE | B11: BNI | C11: INTERMITENTE | D11: BLUMENAU | F11: BLUMENAU | G11: SUL | H11: 7 | I11: =SetorNucleo[[#This Row],[Empresa]]&SetorNucleo[[#This Row],[Setor]] -> CATARINENSEBNI | J11: AVC
A12: CATARINENSE | B12: BNU | C12: RODOVIARIO | D12: BLUMENAU | F12: BLUMENAU | G12: SUL | H12: 1 | I12: =SetorNucleo[[#This Row],[Empresa]]&SetorNucleo[[#This Row],[Setor]] -> CATARINENSEBNU | J12: AVC
A13: CATARINENSE | B13: BRQ | C13: RODOVIARIO | D13: BRUSQUE | F13: BLUMENAU | G13: SUL | H13: 1 | I13: =SetorNucleo[[#This Row],[Empresa]]&SetorNucleo[[#This Row],[Setor]] -> CATARINENSEBRQ | J13: AVC
A14: COMETA | B14: PEI | C14: FRETAMENTO | D14: PEPSICO ITAQUERA (SAO) | E14: SAO_PEPSICO [ITAQUERA] | F14: SAO PAULO G1 | G14: SPO | H14: 3 | I14: =SetorNucleo[[#This Row],[Empresa]]&SetorNucleo[[#This Row],[Setor]] -> COMETAPEI | J14: COM
A15: AV1001 | B15: CBF | C15: RODOVIARIO | D15: CABO FRIO | F15: CABO FRIO | G15: RIO | H15: 4 | I15: =SetorNucleo[[#This Row],[Empresa]]&SetorNucleo[[#This Row],[Setor]] -> AV1001CBF | J15: 1001
A16: AV1001 | B16: CBI | C16: INTERMITENTE | D16: CABO FRIO | F16: CABO FRIO | G16: RIO | H16: 6 | I16: =SetorNucleo[[#This Row],[Empresa]]&SetorNucleo[[#This Row],[Setor]] -> AV1001CBI | J16: 1001
A17: CATARINENSE | B17: CCD | C17: RODOVIARIO | D17: CONCORDIA | F17: FLORIANOPOLIS | G17: SUL | H17: 1 | I17: =SetorNucleo[[#This Row],[Empresa]]&SetorNucleo[[#This Row],[Setor]] -> CATARINENSECCD | J17: AVC
A18: COMETA | B18: SCF | C18: FRETAMENTO | D18: ATECAR - SOROCABA | E18: SCB_ATECAR | F18: SOROCABA | G18: SPO | H18: 3 | I18: =SetorNucleo[[#This Row],[Empresa]]&SetorNucleo[[#This Row],[Setor]] -> COMETASCF | J18: COM
A19: OPÇAO | B19: SCG | C19: FRETAMENTO | D19: SOROCABA - GLOBAL (CPN) | F19: SOROCABA | G19: SPO | H19: 9 | I19: =SetorNucleo[[#This Row],[Empresa]]&SetorNucleo[[#This Row],[Setor]] -> OPÇAOSCG | J19: OPÇ
A20: OPÇAO | B20: SCB | C20: FRETAMENTO | D20: VOTORANTIM (SCB) | E20: SCB_VOTORANTIM [VOTORANTIM] | F20: SOROCABA | G20: SPO | H20: 9 | I20: =SetorNucleo[[#This Row],[Empresa]]&SetorNucleo[[#This Row],[Setor]] -> OPÇAOSCB | J20: OPÇ
A21: OPÇAO | B21: SCV | C21: FRETAMENTO | D21: VOTORANTIM - SALTO (SCB) | E21: SCB_VOTORANTIM [SALTO] | F21: SOROCABA | G21: SPO | H21: 9 | I21: =SetorNucleo[[#This Row],[Empresa]]&SetorNucleo[[#This Row],[Setor]] -> OPÇAOSCV | J21: OPÇ
A22: COMETA | B22: SPF | C22: FRETAMENTO | D22: ATECAR - SAO PAULO | E22: SAO_ATECAR | F22: SAO PAULO G1 | G22: SPO | H22: 3 | I22: =SetorNucleo[[#This Row],[Empresa]]&SetorNucleo[[#This Row],[Setor]] -> COMETASPF | J22: COM
A23: AV1001 | B23: AGR | C23: FRETAMENTO | D23: AGUAS DO RIO (RJO) | E23: RJO_AGUAS DO RIO [RIO] | F23: RIO DE JANEIRO | G23: RIO | H23: 4 | I23: =SetorNucleo[[#This Row],[Empresa]]&SetorNucleo[[#This Row],[Setor]] -> AV1001AGR | J23: 1001
A24: AV1001 | B24: AKR | C24: FRETAMENTO | D24: AKER SLS (MAC) | E24: MAC_AKER SLS [MACAE] | F24: MACAE | G24: RIO | H24: 4 | I24: =SetorNucleo[[#This Row],[Empresa]]&SetorNucleo[[#This Row],[Setor]] -> AV1001AKR | J24: 1001
A25: COMETA | B25: ALM | C25: FRETAMENTO | D25: CBA ALUMINIO | F25: SOROCABA | G25: SPO | H25: 3 | I25: =SetorNucleo[[#This Row],[Empresa]]&SetorNucleo[[#This Row],[Setor]] -> COMETAALM | J25: COM
A26: CATARINENSE | B26: ANG | C26: FRETAMENTO | D26: ANGELONI (ITJ) | E26: JOI_ANGELONI [PORTO BELO] | F26: BLUMENAU | G26: SUL | H26: 1 | I26: =SetorNucleo[[#This Row],[Empresa]]&SetorNucleo[[#This Row],[Setor]] -> CATARINENSEANG | J26: AVC
A27: COMETA | B27: CPI | C27: INTERMITENTE | D27: CAMPINAS - INTERMITENTE | E27: CAMPINAS INTERMITENTE | F27: CAMPINAS | G27: SPO | H27: 5 | I27: =SetorNucleo[[#This Row],[Empresa]]&SetorNucleo[[#This Row],[Setor]] -> COMETACPI | J27: COM
A28: COMETA | B28: BHF | C28: FRETAMENTO | D28: FRANZEN (BHZ) | E28: BHZ_FRANZEN [CONTAGEM] | F28: BELO HORIZONTE | G28: SPO | H28: 3 | I28: =SetorNucleo[[#This Row],[Empresa]]&SetorNucleo[[#This Row],[Setor]] -> COMETABHF | J28: COM
A29: COMETA | B29: CPN | C29: RODOVIARIO | D29: CAMPINAS | F29: CAMPINAS | G29: SPO | H29: 3 | I29: =SetorNucleo[[#This Row],[Empresa]]&SetorNucleo[[#This Row],[Setor]] -> COMETACPN | J29: COM
A30: CATARINENSE | B30: CPN | C30: RODOVIARIO | D30: CAMPINAS | F30: CAMPINAS | G30: SPO | H30: 1 | I30: =SetorNucleo[[#This Row],[Empresa]]&SetorNucleo[[#This Row],[Setor]] -> CATARINENSECPN | J30: AVC
A31: AV1001 | B31: CPS | C31: RODOVIARIO | D31: CAMPOS | F31: CAMPOS | G31: RIO | H31: 4 | I31: =SetorNucleo[[#This Row],[Empresa]]&SetorNucleo[[#This Row],[Setor]] -> AV1001CPS | J31: 1001
A32: AV1001 | B32: CPU | C32: URBANO | D32: CAMPOS - URBANO | F32: CAMPOS | G32: RIO | H32: 4 | I32: =SetorNucleo[[#This Row],[Empresa]]&SetorNucleo[[#This Row],[Setor]] -> AV1001CPU | J32: 1001
A33: CATARINENSE | B33: CTB | C33: RODOVIARIO | D33: CURITIBA | F33: CURITIBA | G33: SUL | H33: 1 | I33: =SetorNucleo[[#This Row],[Empresa]]&SetorNucleo[[#This Row],[Setor]] -> CATARINENSECTB | J33: AVC
A34: COMETA | B34: CTB | C34: RODOVIARIO | D34: CURITIBA | F34: CURITIBA | G34: SUL | H34: 3 | I34: =SetorNucleo[[#This Row],[Empresa]]&SetorNucleo[[#This Row],[Setor]] -> COMETACTB | J34: COM
A35: EXPRESSO DO SUL | B35: CTB | C35: RODOVIARIO | D35: CURITIBA | F35: CURITIBA | G35: SUL | H35: 2 | I35: =SetorNucleo[[#This Row],[Empresa]]&SetorNucleo[[#This Row],[Setor]] -> EXPRESSO DO SULCTB | J35: EXP
A36: CATARINENSE | B36: BMW | C36: FRETAMENTO | D36: BMW (JOI) | E36: JOI_BMW [ARAQUARI] | F36: JOINVILLE | G36: SUL | H36: 1 | I36: =SetorNucleo[[#This Row],[Empresa]]&SetorNucleo[[#This Row],[Setor]] -> CATARINENSEBMW | J36: AVC
A37: COMETA | B37: CAM | C37: FRETAMENTO | D37: AMBEV (CPN) | E37: CPN_AMBEV CERVEJARIA [JAGUARIUNA] | F37: CAMPINAS | G37: SPO | H37: 3 | I37: =SetorNucleo[[#This Row],[Empresa]]&SetorNucleo[[#This Row],[Setor]] -> COMETACAM | J37: COM
A38: CATARINENSE | B38: CTI | C38: INTERMITENTE | D38: CURITIBA | F38: CURITIBA | G38: SUL | H38: 7 | I38: =SetorNucleo[[#This Row],[Empresa]]&SetorNucleo[[#This Row],[Setor]] -> CATARINENSECTI | J38: AVC
A39: COMETA | B39: CTI | C39: INTERMITENTE | D39: CURITIBA | F39: CURITIBA | G39: SUL | H39: 5 | I39: =SetorNucleo[[#This Row],[Empresa]]&SetorNucleo[[#This Row],[Setor]] -> COMETACTI | J39: COM
A40: COMETA | B40: CCN | C40: FRETAMENTO | D40: CNPEM (CPN) | E40: CPN_CNPEM | F40: CAMPINAS | G40: SPO | H40: 3 | I40: =SetorNucleo[[#This Row],[Empresa]]&SetorNucleo[[#This Row],[Setor]] -> COMETACCN | J40: COM
...

Sheet Rodoviária
A1: Destino | B1: Setor
A2: ROD_RIBEIRÃO PRETO (SP) | B2: RAO
A3: ROD_CURITIBA (PR) | B3: CTB
A4: ROD_BALNEÁRIO CAMBORIÚ (SC) | B4: ITJ
A5: ROD_AEROPORTO AFONSO PENA (PR) | B5: CTB
A6: ROD_ANDRELÂNDIA (MG) | B6: SAO
A7: ROD_NITERÓI (RJ) | B7: RIO
A8: ROD_FLORIANÓPOLIS (SC) | B8: FLN
A9: ROD_BELO HORIZONTE (MG) | B9: BHZ
A10: ROD_VOLTA REDONDA (RJ) | B10: RIO
A11: ROD_ÁGUAS DA PRATA (SP) [CNX] | B11: SAO
A12: ROD_DUQUE DE CAXIAS (RJ) | B12: RIO
... A98: ROD_SÃO MIGUEL ARCANJO (SP) | B98: SCB

Sheet d_AUX
A1: Localidades | B1: Sigla | C1: Setor | D1: Abrev | E1: Núcleo | F1: Regional
A2: ARARAQUARA - SP | B2: AQA | C2: ARARAQUARA | D2: AQA | E2: =IFERROR(VLOOKUP(Tabela55[[#This Row],[Abrev]],Nucleos!$B$2:$G$199,5,0),"Verificar com o setor") -> INTERIOR SP | F2: SPO
A3: GR_ARARAQUARA (SP) | B3: GRAQA | C3: ARARAQUARA | D3: AQA | E3: =IFERROR(VLOOKUP(Tabela55[[#This Row],[Abrev]],Nucleos!$B$2:$G$199,5,0),"Verificar com o setor") -> INTERIOR SP | F3: SPO
A4: GT_UNIARA (SP) [GTAQA] | B4: GTAQA | C4: ARARAQUARA | D4: AQA | E4: =IFERROR(VLOOKUP(Tabela55[[#This Row],[Abrev]],Nucleos!$B$2:$G$199,5,0),"Verificar com o setor") -> INTERIOR SP | F4: SPO
A5: GT_EMPRESA CRUZ (SP) | B5: GTAQA. | C5: ARARAQUARA | D5: AQA | E5: =IFERROR(VLOOKUP(Tabela55[[#This Row],[Abrev]],Nucleos!$B$2:$G$199,5,0),"Verificar com o setor") -> INTERIOR SP | F5: SPO
A6: GR_BELO HORIZONTE [ABASTECIMENTO] (MG) | B6: GRBHZ_ABT | C6: BELO HORIZONTE | D6: BHZ | E6: =IFERROR(VLOOKUP(Tabela55[[#This Row],[Abrev]],Nucleos!$B$2:$G$199,5,0),"Verificar com o setor") -> BELO HORIZONTE | F6: SPO
A7: BELO HORIZONTE - MG | B7: BHZ | C7: BELO HORIZONTE | D7: BHZ | E7: =IFERROR(VLOOKUP(Tabela55[[#This Row],[Abrev]],Nucleos!$B$2:$G$199,5,0),"Verificar com o setor") -> BELO HORIZONTE | F7: SPO
A8: BELO HORIZONTE (TERMINAL JK) - MG | B8: TJK | C8: BELO HORIZONTE | D8: BHZ | E8: =IFERROR(VLOOKUP(Tabela55[[#This Row],[Abrev]],Nucleos!$B$2:$G$199,5,0),"Verificar com o setor") -> BELO HORIZONTE | F8: SPO
A9: ROD_BETIM (MG) | B9: BTM | C9: BELO HORIZONTE | D9: BHZ | E9: =IFERROR(VLOOKUP(Tabela55[[#This Row],[Abrev]],Nucleos!$B$2:$G$199,5,0),"Verificar com o setor") -> BELO HORIZONTE | F9: SPO
A10: ROD_AEROPORTO PAMPULHA (MG) | B10: APM | C10: BELO HORIZONTE | D10: BHZ | E10: =IFERROR(VLOOKUP(Tabela55[[#This Row],[Abrev]],Nucleos!$B$2:$G$199,5,0),"Verificar com o setor") -> BELO HORIZONTE | F10: SPO
A11: GR_BELO HORIZONTE (MG) | B11: GRBHZ | C11: BELO HORIZONTE | D11: BHZ | E11: =IFERROR(VLOOKUP(Tabela55[[#This Row],[Abrev]],Nucleos!$B$2:$G$199,5,0),"Verificar com o setor") -> BELO HORIZONTE | F11: SPO
A12: ROD_ROYAL HOTEL LOURDES (MG) | B12: BHR | C12: BELO HORIZONTE | D12: BHZ | E12: =IFERROR(VLOOKUP(Tabela55[[#This Row],[Abrev]],Nucleos!$B$2:$G$199,5,0),"Verificar com o setor") -> BELO HORIZONTE | F12: SPO
A13: GT_BLUMENAU [ABASTECEDOR] (SC) | B13: GTBNU_ABA | C13: BLUMENAU | D13: BNU | E13: =IFERROR(VLOOKUP(Tabela55[[#This Row],[Abrev]],Nucleos!$B$2:$G$199,5,0),"Verificar com o setor") -> BLUMENAU | F13: SUL
... A91: FB_PRF CAMPINA GRANDE DO SUL (PR) [KM 56] | B91: FBCGS | C91: CURITIBA | D91: CTB | E91: =IFERROR(VLOOKUP(Tabela55[[#This Row],[Abrev]],Nucleos!$B$2:$G$199,5,0),"Verificar com o setor") -> CURITIBA | F91: SUL
A92: GR_CAXAMBU (MG) | B92: GRCXB | C92: CAXAMBU | D92: CXB | E92: SAO PAULO G1 | F92: SPO
A93: CAXAMBU - MG | B93: CXB | C93: CAXAMBU | D93: CXB | E93: SAO PAULO G1 | F93: SPO
A94: CRUZILIA - MG | B94: CZI | C94: CAXAMBU | D94: CXB | E94: SAO PAULO G1 | F94: SPO
A95: ANDRELANDIA - MG | B95: AND | C95: CAXAMBU | D95: CXB | E95: SAO PAULO G1 | F95: SPO
A96: CONCEICAO DO RIO VERDE - MG | B96: CRV | C96: CAXAMBU | D96: CXB | E96: SAO PAULO G1 | F96: SPO
A97: SAO LOURENCO - MG | B97: SLO | C97: CAXAMBU | D97: CXB | E97: SAO PAULO G1 | F97: SPO
A98: FLORIANOPOLIS - SC | B98: FLN | C98: FLORIANOPOLIS | D98: FLN | E98: =IFERROR(VLOOKUP(Tabela55[[#This Row],[Abrev]],Nucleos!$B$2:$G$199,5,0),"Verificar com o setor") -> FLORIANOPOLIS | F98: SUL
A99: GT_PORTO ALEGRE (RS) [PLANALTO] | B99: GTPAP | C99: PORTO ALEGRE | D99: POA | E99: =IFERROR(VLOOKUP(Tabela55[[#This Row],[Abrev]],Nucleos!$B$2:$G$199,5,0),"Verificar com o setor") -> FLORIANOPOLIS | F99: SUL
A100: PORTO ALEGRE - RS | B100: POA | C100: PORTO ALEGRE | D100: POA | E100: =IFERROR(VLOOKUP(Tabela55[[#This Row],[Abrev]],Nucleos!$B$2:$G$199,5,0),"Verificar com o setor") -> FLORIANOPOLIS | F100: SUL
A101: CRICIUMA - SC | B101: CRM | C101: FLORIANOPOLIS | D101: FLN | E101: =IFERROR(VLOOKUP(Tabela55[[#This Row],[Abrev]],Nucleos!$B$2:$G$199,5,0),"Verificar com o setor") -> FLORIANOPOLIS | F101: SUL
A102: GT_ARARANGUÁ (SC) | B102: GTARG | C102: FLORIANOPOLIS | D102: FLN | E102: =IFERROR(VLOOKUP(Tabela55[[#This Row],[Abrev]],Nucleos!$B$2:$G$199,5,0),"Verificar com o setor") -> FLORIANOPOLIS | F102: SUL
A103: ARARANGUA - SC | B103: ARG | C103: FLORIANOPOLIS | D103: FLN | E103: =IFERROR(VLOOKUP(Tabela55[[#This Row],[Abrev]],Nucleos!$B$2:$G$199,5,0),"Verificar com o setor") -> FLORIANOPOLIS | F103: SUL
A104: GT_SANTA MARIA (RS) | B104: GTSTM | C104: FLORIANOPOLIS | D104: FLN | E104: =IFERROR(VLOOKUP(Tabela55[[#This Row],[Abrev]],Nucleos!$B$2:$G$199,5,0),"Verificar com o setor") -> FLORIANOPOLIS | F104: SUL
A105: SANTA MARIA - RS | B105: STM | C105: FLORIANOPOLIS | D105: FLN | E105: =IFERROR(VLOOKUP(Tabela55[[#This Row],[Abrev]],Nucleos!$B$2:$G$199,5,0),"Verificar com o setor") -> FLORIANOPOLIS | F105: SUL
A106: VIDEIRA - SC | B106: VDR | C106: FLORIANOPOLIS | D106: FLN | E106: =IFERROR(VLOOKUP(Tabela55[[#This Row],[Abrev]],Nucleos!$B$2:$G$199,5,0),"Verificar com o setor") -> FLORIANOPOLIS | F106: SUL
A107: TUBARAO - SC | B107: TUB | C107: FLORIANOPOLIS | D107: FLN | E107: =IFERROR(VLOOKUP(Tabela55[[#This Row],[Abrev]],Nucleos!$B$2:$G$199,5,0),"Verificar com o setor") -> FLORIANOPOLIS | F107: SUL
A108: SÃO JOSÉ (SC) | B108: SJO | C108: FLORIANOPOLIS | D108: FLN | E108: =IFERROR(VLOOKUP(Tabela55[[#This Row],[Abrev]],Nucleos!$B$2:$G$199,5,0),"Verificar com o setor") -> FLORIANOPOLIS | F108: SUL
A109: GT_VIDEIRA (SC) | B109: GTVDR | C109: FLORIANOPOLIS | D109: FLN | E109: =IFERROR(VLOOKUP(Tabela55[[#This Row],[Abrev]],Nucleos!$B$2:$G$199,5,0),"Verificar com o setor") -> FLORIANOPOLIS | F109: SUL
... A176: GR_JUÍZ DE FORA (MG) | B176: GRJDF | C176: JUIZ DE FORA | D176: JDF | E176: =IFERROR(VLOOKUP(Tabela55[[#This Row],[Abrev]],Nucleos!$B$2:$G$199,5,0),"Verificar com o setor") -> JUIZ DE FORA | F176: SPO
A177: JUNDIAI - SP | B177: JDI | C177: JUNDIAÍ | D177: JDI | E177: JUNDIAÍ | F177: SPO
A178: GR_JUNDIAÍ (SP) | B178: GRJDI | C178: JUNDIAÍ | D178: JDI | E178: JUNDIAÍ | F178: SPO
A179: GT_JARAGUÁ DO SUL (SC) | B179: GTJGS | C179: JOINVILLE | D179: JOI | E179: =IFERROR(VLOOKUP(Tabela55[[#This Row],[Abrev]],Nucleos!$B$2:$G$199,5,0),"Verificar com o setor") -> JOINVILLE | F179: SUL
A180: JARAGUA DO SUL - SC | B180: JGS | C180: JOINVILLE | D180: JOI | E180: =IFERROR(VLOOKUP(Tabela55[[#This Row],[Abrev]],Nucleos!$B$2:$G$199,5,0),"Verificar com o setor") -> JOINVILLE | F180: SUL
A181: JOINVILLE - SC | B181: JOI | C181: JOINVILLE | D181: JOI | E181: =IFERROR(VLOOKUP(Tabela55[[#This Row],[Abrev]],Nucleos!$B$2:$G$199,5,0),"Verificar com o setor") -> JOINVILLE | F181: SUL
A182: GT_MAFRA (SC) | B182: GTMFR | C182: JOINVILLE | D182: JOI | E182: =IFERROR(VLOOKUP(Tabela55[[#This Row],[Abrev]],Nucleos!$B$2:$G$199,5,0),"Verificar com o setor") -> JOINVILLE | F182: SUL
A183: GT_MAFRA (SC) | B183: GTMRF | C183: JOINVILLE | D183: JOI | E183: =IFERROR(VLOOKUP(Tabela55[[#This Row],[Abrev]],Nucleos!$B$2:$G$199,5,0),"Verificar com o setor") -> JOINVILLE | F183: SUL
...

Sheet Planilha1
A1: PT_CENTRO [LONDRINA] (PR) | B1: Londrina | C1: LDN | D1: Curitiba | E1: Sul
A2: ROD_GUARATUBA (PR) | B2: Curitiba | C2: CTB | D2: Curitiba | E2: Sul
A3: ROD_GASPAR (SC) | B3: Blumenau | C3: BNU | D3: Blumenau | E3: Sul
A4: RESTAURANTE PANORÂMICO (PR) | B4: Guarapuava | C4: GRP | D4: Curitiba | E4: Sul
A5: BETO CARRERO WORLD (SC) | B5: Blumenau | C5: BCW | D5: Blumenau | E5: Sul
A6: SERRA DOURADA [REALEZA] (PR) | B6: Curitiba | C6: CTB | D6: Curitiba | E6: Sul
A7: GRAMADINHO [ITAPETININGA] (SP) | B7: São Paulo | C7: SPO | D7: São Paulo | E7: Sul
A8: ROD_MEDIANEIRA (PR) | B8: Foz do Iguaçu | C8: MDN | D8: Foz do Iguaçu | E8: Sul
A9: PT_CENTRO [ITANHAÉM] (SP) | B9: São Paulo | C9: SPO | D9: São Paulo | E9: Sul
A10: PRF CAMPINA GRANDE DO SUL (PR) [KM 56] | B10: Curitiba | C10: CTB | D10: Curitiba | E10: Sul
A11: RESTAURANTE MONTE CARLO II (PR) | B11: Blumenau | C11: BNU | D11: Blumenau | E11: Sul

Sheet d_Aux_SalesForce
A1: Localidade | B1: Sigla
A2: AGUAS DA PRATA - M. DIVISORIO(SP) | B2: AGP
A3: AGUAS DA PRATA(SP) | B3: AGP
A4: ALCANTARA(RJ) | B4: ALC
A5: APARECIDA(SP) | B5: APA
A6: ARARAQUARA(SP) | B6: AQA
A7: ARARUAMA(RJ) | B7: ARA
A8: ARRAIAL DO CABO(RJ) | B8: ARR
A9: BACAXA(RJ) | B9: BCX
A10: BALNEARIO CAMBORIU(SC) | B10: CMB
A11: BARRA DE SAO JOAO(RJ) | B11: BSJ
A12: BELO HORIZONTE(MG) | B12: BHZ
... A125: SAO PAULO - AEROP. CONGONHAS(SP) | B125: CGH
